Workbook
Name Discount: Inputs!$C$28
Name DriverName: Inputs!$B$34:$B$42
Name DriverQty: Inputs!$C$34:$C$42
Name MarginFloor: Inputs!$C$27
Name MarginLever: Inputs!$C$26
Name Months: Inputs!$C$16
Name MonVisits: Inputs!$C$21
Name MonVisitsPerSite: Inputs!$C$17
Name Patients: Inputs!$C$14
Name SiteMonths: Inputs!$C$22
Name Sites: Inputs!$C$13
Name TotalVisits: Inputs!$C$20
Name VisitsPerPatient: Inputs!$C$15
Name Weeks: Inputs!$C$23

Sheet Inputs
B2: PriceDeskLY
B3: Study pricing model - all amounts in INR
B5: HOW TO USE
B6: - Blue cells are yours to edit. Black cells are formulas - do not overwrite them.
B7: - Set the study drivers and commercial levers below, then mark lines with "x" in column A of the Quote sheet.
B8: - Margin is applied line by line, then summed. It is a share of the invoice, not a mark-up on cost.
B9: - Pass-through and Tech lines bill at cost: no margin, no discount, excluded from revenue.
B10: - Summary shows the roll-up. Checks must all read OK before the quote goes out.
B12: STUDY DRIVERS
B13: Sites | C13: 5
B14: Patients enrolled | C14: 250
B15: Visits per patient | C15: 3
B16: Study duration (months) | C16: 12
B17: Monitoring visits per site | C17: 4
B19: DERIVED
B20: Total patient visits | C20: =Patients*VisitsPerPatient -> 750
B21: Total monitoring visits | C21: =Sites*MonVisitsPerSite -> 20
B22: Site-months | C22: =Sites*Months -> 60
B23: Weeks | C23: =ROUND(Months*4.345,0) -> 52
B25: COMMERCIAL LEVERS
B26: Margin on invoice | C26: 0.225 | D26: share of the invoice, not a mark-up on cost
B27: Margin floor (policy) | C27: 0.225 | D27: 22.5% minimum on every sale
B28: Client discount | C28: 0 | D28: applies to professional fees only, never to pass-through
B29: Margin needed for this discount | C29: =1-(1-MarginFloor)*(1-Discount) -> 0.225 | D29: set Margin on invoice to at least this to hold the floor
B32: DRIVER TO QUANTITY | D32: the Quote sheet looks quantities up here
B33: Driver | C33: Quantity
B34: Fixed | C34: =1 -> 1
B35: Per site | C35: =Sites -> 5
B36: Per visit | C36: =TotalVisits -> 750
B37: Per month | C37: =Months -> 12
B38: Per site-month | C38: =SiteMonths -> 60
B39: Per week | C39: =Weeks -> 52
B40: Per monitoring visit | C40: =MonVisits -> 20
B41: Per patient | C41: =Patients -> 250
B42: Manual | C42: =1 -> 1

Sheet Rate Card
A1: Department | B1: Task | C1: Kind | D1: Driver | E1: Delivery hrs | F1: Delivery rate | G1: Review hrs | H1: Review rate | I1: Unit cost | J1: Rate set?
A2: Medical | B2: Concept Note Writing | C2: Service | D2: Fixed | E2: 16 | F2: 950 | G2: 5 | H2: 3000 | I2: =IFERROR(N(E2)*N(F2)+N(G2)*N(H2),0) -> 30200 | J2: =IF(N(I2)>0,"OK","RATE NOT SET") -> OK
A3: Medical | B3: Literature Review/Search (Can vary based on Scope and extent of data) | C3: Service | D3: Fixed | E3: 24 | F3: 950 | G3: 4 | H3: 3000 | I3: =IFERROR(N(E3)*N(F3)+N(G3)*N(H3),0) -> 34800 | J3: =IF(N(I3)>0,"OK","RATE NOT SET") -> OK
A4: Medical | B4: Protocol Writing -Post Marketing/RWE | C4: Service | D4: Fixed | E4: 70 | F4: 950 | G4: 18 | H4: 3000 | I4: =IFERROR(N(E4)*N(F4)+N(G4)*N(H4),0) -> 120500 | J4: =IF(N(I4)>0,"OK","RATE NOT SET") -> OK
A5: Medical | B5: Protocol Writing -Phase 4 | C5: Service | D5: Fixed | E5: 70 | F5: 950 | G5: 18 | H5: 3000 | I5: =IFERROR(N(E5)*N(F5)+N(G5)*N(H5),0) -> 120500 | J5: =IF(N(I5)>0,"OK","RATE NOT SET") -> OK
A6: Medical | B6: ICD (n=1; English) | C6: Service | D6: Fixed | E6: 18 | F6: 950 | G6: 4 | H6: 3000 | I6: =IFERROR(N(E6)*N(F6)+N(G6)*N(H6),0) -> 29100 | J6: =IF(N(I6)>0,"OK","RATE NOT SET") -> OK
A7: Medical | B7: ICD + Ascent (n=1; English) | C7: Service | D7: Fixed | E7: 19 | F7: 950 | G7: 4.25 | H7: 3000 | I7: =IFERROR(N(E7)*N(F7)+N(G7)*N(H7),0) -> 30800 | J7: =IF(N(I7)>0,"OK","RATE NOT SET") -> OK
A8: Medical | B8: Data variable enlisting for DCF/CRF preparation | C8: Service | D8: Fixed | E8: 6 | F8: 950 | G8: 1 | H8: 3000 | I8: =IFERROR(N(E8)*N(F8)+N(G8)*N(H8),0) -> 8700 | J8: =IF(N(I8)>0,"OK","RATE NOT SET") -> OK
A9: Medical | B9: Site Feasibility Questionnaire (Post Concept Finalization) | C9: Service | D9: Fixed | E9: 3.5 | F9: 950 | G9: 1 | H9: 3000 | I9: =IFERROR(N(E9)*N(F9)+N(G9)*N(H9),0) -> 6325 | J9: =IF(N(I9)>0,"OK","RATE NOT SET") -> OK
A10: Medical | B10: Feasibility Questionnaire (e.g. Study Feasibility/Survey) | C10: Service | D10: Fixed | E10: 3.5 | F10: 950 | G10: 2 | H10: 3000 | I10: =IFERROR(N(E10)*N(F10)+N(G10)*N(H10),0) -> 9325 | J10: =IF(N(I10)>0,"OK","RATE NOT SET") -> OK
A11: Medical | B11: Investigator meeting deck | C11: Service | D11: Fixed | E11: 7 | F11: 950 | G11: 4 | H11: 3000 | I11: =IFERROR(N(E11)*N(F11)+N(G11)*N(H11),0) -> 18650 | J11: =IF(N(I11)>0,"OK","RATE NOT SET") -> OK
A12: Medical | B12: Protocol Training Deck | C12: Service | D12: Fixed | E12: 12 | F12: 950 | G12: 3 | H12: 3000 | I12: =IFERROR(N(E12)*N(F12)+N(G12)*N(H12),0) -> 20400 | J12: =IF(N(I12)>0,"OK","RATE NOT SET") -> OK
A13: Medical | B13: SAP - Dummy tables (overlaps with stats) | C13: Service | D13: Fixed | E13: 12 | F13: 950 | G13: 4 | H13: 3000 | I13: =IFERROR(N(E13)*N(F13)+N(G13)*N(H13),0) -> 23400 | J13: =IF(N(I13)>0,"OK","RATE NOT SET") -> OK
A14: Medical | B14: SAR (overlaps with stats) (review, varies as per study depth) | C14: Service | D14: Fixed | F14: 950 | G14: 24 | H14: 3000 | I14: =IFERROR(N(E14)*N(F14)+N(G14)*N(H14),0) -> 72000 | J14: =IF(N(I14)>0,"OK","RATE NOT SET") -> OK
A15: Medical | B15: Statistical Analysis (Varies based on quantum and variables) (review) | C15: Service | D15: Fixed | F15: 950 | G15: 16 | H15: 3000 | I15: =IFERROR(N(E15)*N(F15)+N(G15)*N(H15),0) -> 48000 | J15: =IF(N(I15)>0,"OK","RATE NOT SET") -> OK
A16: Medical | B16: Slide Deck (25 slides; Can vary based on Objective; includes RFP deck, interim report etc.) | C16: Service | D16: Fixed | E16: 28 | F16: 950 | G16: 8 | H16: 3000 | I16: =IFERROR(N(E16)*N(F16)+N(G16)*N(H16),0) -> 50600 | J16: =IF(N(I16)>0,"OK","RATE NOT SET") -> OK
A17: Medical | B17: CSR | C17: Service | D17: Fixed | E17: 28 | F17: 950 | G17: 28 | H17: 3000 | I17: =IFERROR(N(E17)*N(F17)+N(G17)*N(H17),0) -> 110600 | J17: =IF(N(I17)>0,"OK","RATE NOT SET") -> OK
A18: Medical | B18: Journal Selection and list development | C18: Service | D18: Fixed | E18: 8 | F18: 950 | G18: 1.5 | H18: 3000 | I18: =IFERROR(N(E18)*N(F18)+N(G18)*N(H18),0) -> 12100 | J18: =IF(N(I18)>0,"OK","RATE NOT SET") -> OK
A19: Medical | B19: MS writing (Original article for clinical studies) | C19: Service | D19: Fixed | E19: 80 | F19: 950 | G19: 24 | H19: 3000 | I19: =IFERROR(N(E19)*N(F19)+N(G19)*N(H19),0) -> 148000 | J19: =IF(N(I19)>0,"OK","RATE NOT SET") -> OK
A20: Medical | B20: MS writing - Review article (Narrative/SLR) (including literature search and finalization) | C20: Service | D20: Fixed | E20: 80 | F20: 950 | G20: 35 | H20: 3000 | I20: =IFERROR(N(E20)*N(F20)+N(G20)*N(H20),0) -> 181000 | J20: =IF(N(I20)>0,"OK","RATE NOT SET") -> OK
A21: Medical | B21: Abstract for Conference (1st draft for Client's review and approval) | C21: Service | D21: Fixed | E21: 110 | F21: 950 | G21: 5 | H21: 3000 | I21: =IFERROR(N(E21)*N(F21)+N(G21)*N(H21),0) -> 119500 | J21: =IF(N(I21)>0,"OK","RATE NOT SET") -> OK
A22: Medical | B22: Poster in ppt format (1st draft for Client's review and approval) | C22: Service | D22: Fixed | E22: 16 | F22: 950 | G22: 10 | H22: 3000 | I22: =IFERROR(N(E22)*N(F22)+N(G22)*N(H22),0) -> 45200 | J22: =IF(N(I22)>0,"OK","RATE NOT SET") -> OK
A23: Medical | B23: Submission package preparation and journal submission (varies as per journal requirement) | C23: Service | D23: Fixed | E23: 35 | F23: 950 | G23: 1 | H23: 3000 | I23: =IFERROR(N(E23)*N(F23)+N(G23)*N(H23),0) -> 36250 | J23: =IF(N(I23)>0,"OK","RATE NOT SET") -> OK
A24: Medical | B24: Minor Revisions of Submitted Manuscript and Re-submission (Reviewer comments post submission) | C24: Service | D24: Fixed | E24: 12 | F24: 950 | G24: 4 | H24: 3000 | I24: =IFERROR(N(E24)*N(F24)+N(G24)*N(H24),0) -> 23400 | J24: =IF(N(I24)>0,"OK","RATE NOT SET") -> OK
A25: Medical | B25: Major Revisions of Submitted Manuscript and Re-submission (Reviewer comments post submission) | C25: Service | D25: Fixed | E25: 40 | F25: 950 | G25: 12 | H25: 3000 | I25: =IFERROR(N(E25)*N(F25)+N(G25)*N(H25),0) -> 74000 | J25: =IF(N(I25)>0,"OK","RATE NOT SET") -> OK
A26: Medical | B26: Other Activities (Grant writing, RFP documents) | C26: Service | D26: Fixed | E26: 40 | F26: 950 | G26: 12 | H26: 3000 | I26: =IFERROR(N(E26)*N(F26)+N(G26)*N(H26),0) -> 74000 | J26: =IF(N(I26)>0,"OK","RATE NOT SET") -> OK
A27: SSU | B27: Site Identification (per site) | C27: Service | D27: Per site | E27: 0.5 | F27: 800 | G27: 0 | H27: 3000 | I27: =IFERROR(N(E27)*N(F27)+N(G27)*N(H27),0) -> 400 | J27: =IF(N(I27)>0,"OK","RATE NOT SET") -> OK
... A47: SSU | B47: ISF Support | C47: Service | D47: Per site | E47: 16 | F47: 800 | G47: 0 | H47: 3000 | I47: =IFERROR(N(E47)*N(F47)+N(G47)*N(H47),0) -> 12800 | J47: =IF(N(I47)>0,"OK","RATE NOT SET") -> OK
A48: SSU | B48: eISF support | C48: Service | D48: Per site | F48: 800 | G48: 0 | H48: 3000 | I48: =IFERROR(N(E48)*N(F48)+N(G48)*N(H48),0) -> 0 | J48: =IF(N(I48)>0,"OK","RATE NOT SET") -> RATE NOT SET
A49: DM | B49: Protocol Training | C49: Service | D49: Fixed | E49: 25 | F49: 850 | G49: 0 | H49: 3000 | I49: =IFERROR(N(E49)*N(F49)+N(G49)*N(H49),0) -> 21250 | J49: =IF(N(I49)>0,"OK","RATE NOT SET") -> OK
A50: DM | B50: DMP development and finalization | C50: Service | D50: Fixed | E50: 50 | F50: 850 | G50: 2 | H50: 3000 | I50: =IFERROR(N(E50)*N(F50)+N(G50)*N(H50),0) -> 48500 | J50: =IF(N(I50)>0,"OK","RATE NOT SET") -> OK
A51: DM | B51: CRF Development (upto 50 pages) | C51: Service | D51: Fixed | E51: 120 | F51: 850 | G51: 0 | H51: 3000 | I51: =IFERROR(N(E51)*N(F51)+N(G51)*N(H51),0) -> 102000 | J51: =IF(N(I51)>0,"OK","RATE NOT SET") -> OK
A52: DM | B52: CRF Finalization | C52: Service | D52: Fixed | E52: 50 | F52: 850 | G52: 1 | H52: 3000 | I52: =IFERROR(N(E52)*N(F52)+N(G52)*N(H52),0) -> 45500 | J52: =IF(N(I52)>0,"OK","RATE NOT SET") -> OK
A53: DM | B53: DCF development (on paper CRF) | C53: Service | D53: Fixed | E53: 40 | F53: 850 | G53: 0 | H53: 3000 | I53: =IFERROR(N(E53)*N(F53)+N(G53)*N(H53),0) -> 34000 | J53: =IF(N(I53)>0,"OK","RATE NOT SET") -> OK
A54: DM | B54: DCF development (no paper CRF) | C54: Service | D54: Fixed | E54: 80 | F54: 850 | G54: 0 | H54: 3000 | I54: =IFERROR(N(E54)*N(F54)+N(G54)*N(H54),0) -> 68000 | J54: =IF(N(I54)>0,"OK","RATE NOT SET") -> OK
A55: DM | B55: EDC finalization | C55: Service | D55: Fixed | E55: 50 | F55: 850 | G55: 0 | H55: 3000 | I55: =IFERROR(N(E55)*N(F55)+N(G55)*N(H55),0) -> 42500 | J55: =IF(N(I55)>0,"OK","RATE NOT SET") -> OK
A56: DM | B56: EDC UAT- Demo | C56: Service | D56: Fixed | E56: 80 | F56: 850 | G56: 0 | H56: 3000 | I56: =IFERROR(N(E56)*N(F56)+N(G56)*N(H56),0) -> 68000 | J56: =IF(N(I56)>0,"OK","RATE NOT SET") -> OK
A57: DM | B57: EDC UAT- Production | C57: Service | D57: Fixed | E57: 5 | F57: 850 | G57: 1 | H57: 3000 | I57: =IFERROR(N(E57)*N(F57)+N(G57)*N(H57),0) -> 7250 | J57: =IF(N(I57)>0,"OK","RATE NOT SET") -> OK
A58: DM | B58: Data Digitization | C58: Service | D58: Per visit | E58: 1 | F58: 850 | G58: 0 | H58: 3000 | I58: =IFERROR(N(E58)*N(F58)+N(G58)*N(H58),0) -> 850 | J58: =IF(N(I58)>0,"OK","RATE NOT SET") -> OK
A59: DM | B59: Trackers update | C59: Service | D59: Per month | E59: 1.5 | F59: 850 | G59: 10 | H59: 3000 | I59: =IFERROR(N(E59)*N(F59)+N(G59)*N(H59),0) -> 31275 | J59: =IF(N(I59)>0,"OK","RATE NOT SET") -> OK
...

Sheet Summary
B2: Quote summary
B3: Every figure below is a roll-up of the Quote sheet. Nothing is typed here.
B5: Lines included | C5: =COUNTIF(Quote!$A$2:$A$123,"x") -> 33
B6: Total fixed fee (cost) | C6: =SUMIFS(Quote!$L$2:$L$123,Quote!$D$2:$D$123,"Service") -> 3806350 | D6: sum of Line cost on service lines
B7: Sum of line prices | C7: =SUMIFS(Quote!$K$2:$K$123,Quote!$D$2:$D$123,"Service") -> 4912119 | D7: sum of Line price - margin already inside each line
B8: Margin (rupees) | C8: =C7-C6 -> 1105769 | D8: the difference, not a separate uplift
B9: Discount | C9: =-C7*Discount -> 0 | D9: professional fees only
B10: Net revenue | C10: =C7+C9 -> 4912119 | D10: what you actually earn
B11: Pass-through at cost | C11: =SUMIFS(Quote!$L$2:$L$123,Quote!$D$2:$D$123,"Pass-through") -> 100000 | D11: no margin, no discount, not revenue
B12: Client price | C12: =C10+C11 -> 5012119 | D12: total invoice
B13: Margin on revenue | C13: =IF(C10=0,0,(C10-C6)/C10) -> 0.22511039 | D13: must be at or above the floor
B14: Uplift on cost | C14: =IF(C6=0,0,(C7-C6)/C6) -> 0.29050639 | D14: what 22.5% margin looks like as a mark-up
B15: Delivery hours | C15: =SUM(Quote!M2:M123) -> 3984
B16: Review hours | C16: =SUM(Quote!N2:N123) -> 73.5
B19: BY DEPARTMENT
B20: Department | C20: Lines | D20: Cost | E20: Price | F20: Share of price
B21: Medical | C21: =COUNTIFS(Quote!$A$2:$A$123,"x",Quote!$B$2:$B$123,$B21) -> 8 | D21: =SUMIFS(Quote!$L$2:$L$123,Quote!$B$2:$B$123,$B21) -> 360625 | E21: =SUMIFS(Quote!$K$2:$K$123,Quote!$B$2:$B$123,$B21) -> 465323 | F21: =IF($E$30=0,0,E21/$E$30) -> 0.092839575
B22: SSU | C22: =COUNTIFS(Quote!$A$2:$A$123,"x",Quote!$B$2:$B$123,$B22) -> 10 | D22: =SUMIFS(Quote!$L$2:$L$123,Quote!$B$2:$B$123,$B22) -> 133300 | E22: =SUMIFS(Quote!$K$2:$K$123,Quote!$B$2:$B$123,$B22) -> 172005 | F22: =IF($E$30=0,0,E22/$E$30) -> 0.03431782
B23: DM | C23: =COUNTIFS(Quote!$A$2:$A$123,"x",Quote!$B$2:$B$123,$B23) -> 8 | D23: =SUMIFS(Quote!$L$2:$L$123,Quote!$B$2:$B$123,$B23) -> 2794025 | E23: =SUMIFS(Quote!$K$2:$K$123,Quote!$B$2:$B$123,$B23) -> 3605872 | F23: =IF($E$30=0,0,E23/$E$30) -> 0.71943064
B24: PM | C24: =COUNTIFS(Quote!$A$2:$A$123,"x",Quote!$B$2:$B$123,$B24) -> 4 | D24: =SUMIFS(Quote!$L$2:$L$123,Quote!$B$2:$B$123,$B24) -> 494400 | E24: =SUMIFS(Quote!$K$2:$K$123,Quote!$B$2:$B$123,$B24) -> 637951 | F24: =IF($E$30=0,0,E24/$E$30) -> 0.12728169
B25: SM | C25: =COUNTIFS(Quote!$A$2:$A$123,"x",Quote!$B$2:$B$123,$B25) -> 0 | D25: =SUMIFS(Quote!$L$2:$L$123,Quote!$B$2:$B$123,$B25) -> 0 | E25: =SUMIFS(Quote!$K$2:$K$123,Quote!$B$2:$B$123,$B25) -> 0 | F25: =IF($E$30=0,0,E25/$E$30) -> 0
B26: EC | C26: =COUNTIFS(Quote!$A$2:$A$123,"x",Quote!$B$2:$B$123,$B26) -> 2 | D26: =SUMIFS(Quote!$L$2:$L$123,Quote!$B$2:$B$123,$B26) -> 24000 | E26: =SUMIFS(Quote!$K$2:$K$123,Quote!$B$2:$B$123,$B26) -> 30968 | F26: =IF($E$30=0,0,E26/$E$30) -> 0.0061786243
B27: BioStats | C27: =COUNTIFS(Quote!$A$2:$A$123,"x",Quote!$B$2:$B$123,$B27) -> 0 | D27: =SUMIFS(Quote!$L$2:$L$123,Quote!$B$2:$B$123,$B27) -> 0 | E27: =SUMIFS(Quote!$K$2:$K$123,Quote!$B$2:$B$123,$B27) -> 0 | F27: =IF($E$30=0,0,E27/$E$30) -> 0
B28: PTC | C28: =COUNTIFS(Quote!$A$2:$A$123,"x",Quote!$B$2:$B$123,$B28) -> 1 | D28: =SUMIFS(Quote!$L$2:$L$123,Quote!$B$2:$B$123,$B28) -> 100000 | E28: =SUMIFS(Quote!$K$2:$K$123,Quote!$B$2:$B$123,$B28) -> 100000 | F28: =IF($E$30=0,0,E28/$E$30) -> 0.019951641
B29: Tech | C29: =COUNTIFS(Quote!$A$2:$A$123,"x",Quote!$B$2:$B$123,$B29) -> 0 | D29: =SUMIFS(Quote!$L$2:$L$123,Quote!$B$2:$B$123,$B29) -> 0 | E29: =SUMIFS(Quote!$K$2:$K$123,Quote!$B$2:$B$123,$B29) -> 0 | F29: =IF($E$30=0,0,E29/$E$30) -> 0
B30: Total | C30: =SUM(C21:C29) -> 33 | D30: =SUM(D21:D29) -> 3906350 | E30: =SUM(E21:E29) -> 5012119

Sheet Checks
B2: Model checks
B3: All must read OK before this quote leaves the building.
B5: # | C5: Check | D5: Result | E5: Status
B6: 1 | C6: Line prices roll up to the quoted fees | D6: =ROUND(SUMIFS(Quote!$K$2:$K$123,Quote!$D$2:$D$123,"Service")-Summary!C7,2) -> 0 | E6: =IF(D6=0,"OK","FAIL") -> OK
B7: 2 | C7: Qty x Unit price = Line price on every row | D7: =SUMPRODUCT(--(ROUND(Quote!$F$2:$F$123*Quote!$J$2:$J$123,2)<>ROUND(Quote!$K$2:$K$123,2))) -> 0 | E7: =IF(D7=0,"OK","FAIL") -> OK
B8: 3 | C8: Realised margin at or above the floor | D8: =Summary!C13-MarginFloor -> 0.00011038515 | E8: =IF(D8>=-0.0005,"OK","FAIL") -> OK
B9: 4 | C9: Margin lever at or above the floor | D9: =MarginLever-MarginFloor -> 0 | E9: =IF(D9>=0,"OK","FAIL") -> OK
B10: 5 | C10: Included lines with no rate set | D10: =COUNTIFS(Quote!$A$2:$A$123,"x",Quote!$G$2:$G$123,0) -> 0 | E10: =IF(D10=0,"OK","FAIL") -> OK
B11: 6 | C11: Included lines resolving to zero quantity | D11: =COUNTIFS(Quote!$A$2:$A$123,"x",Quote!$F$2:$F$123,0) -> 0 | E11: =IF(D11=0,"OK","REVIEW") -> OK
B12: 7 | C12: Line margin overrides below the floor | D12: =SUMPRODUCT(--(Quote!$H$2:$H$123<>""),--(Quote!$H$2:$H$123<MarginFloor)) -> 0 | E12: =IF(D12=0,"OK","FAIL") -> OK
B13: 8 | C13: Pass-through lines carrying margin | D13: =SUMPRODUCT(--(Quote!$D$2:$D$123="Pass-through"),--(Quote!$I$2:$I$123>0)) -> 0 | E13: =IF(D13=0,"OK","FAIL") -> OK
B14: 9 | C14: Lines where margin differs from the lever | D14: =SUMPRODUCT(--(Quote!$A$2:$A$123="x"),--(Quote!$D$2:$D$123="Service"),--(Quote!$I$2:$I$123<>MarginLever)) -> 0 | E14: =IF(D14=0,"OK","REVIEW") -> OK
B15: 10 | C15: Discount leaves margin under the floor | D15: =IF(Summary!C13<MarginFloor-0.0005,1,0) -> 0 | E15: =IF(D15=0,"OK","FAIL") -> OK
C18: Checks 6 and 9 read REVIEW rather than FAIL: both can be legitimate, but must be deliberate.
C19: Contingency is deliberately absent from this model. It plays no part in the calculation.

Sheet Quote
A1: In | B1: Department | C1: Activity | D1: Kind | E1: Driver | F1: Qty | G1: Unit cost | H1: Margin override | I1: Margin applied | J1: Unit price | K1: Line price | L1: Line cost | M1: Delivery hrs | N1: Review hrs
A2: x | B2: ='Rate Card'!A2 -> Medical | C2: ='Rate Card'!B2 -> Concept Note Writing | D2: ='Rate Card'!C2 -> Service | E2: ='Rate Card'!D2 -> Fixed | F2: =IF($A2="x",IFERROR(INDEX(DriverQty,MATCH($E2,DriverName,0)),0),0) -> 1 | G2: ='Rate Card'!I2 -> 30200 | I2: =IF($D2="Pass-through",0,MAX(MarginFloor,IF($H2="",MarginLever,$H2))) -> 0.225 | J2: =IF($D2="Pass-through",$G2,IF($I2>=1,$G2,ROUND($G2/(1-$I2),0))) -> 38968 | K2: =$F2*$J2 -> 38968 | L2: =$F2*$G2 -> 30200 | M2: =$F2*N('Rate Card'!E2) -> 16 | N2: =$F2*N('Rate Card'!G2) -> 5
A3: x | B3: ='Rate Card'!A3 -> Medical | C3: ='Rate Card'!B3 -> Literature Review/Search (Can vary based on Scope and extent of data) | D3: ='Rate Card'!C3 -> Service | E3: ='Rate Card'!D3 -> Fixed | F3: =IF($A3="x",IFERROR(INDEX(DriverQty,MATCH($E3,DriverName,0)),0),0) -> 1 | G3: ='Rate Card'!I3 -> 34800 | I3: =IF($D3="Pass-through",0,MAX(MarginFloor,IF($H3="",MarginLever,$H3))) -> 0.225 | J3: =IF($D3="Pass-through",$G3,IF($I3>=1,$G3,ROUND($G3/(1-$I3),0))) -> 44903 | K3: =$F3*$J3 -> 44903 | L3: =$F3*$G3 -> 34800 | M3: =$F3*N('Rate Card'!E3) -> 24 | N3: =$F3*N('Rate Card'!G3) -> 4
A4: x | B4: ='Rate Card'!A4 -> Medical | C4: ='Rate Card'!B4 -> Protocol Writing -Post Marketing/RWE | D4: ='Rate Card'!C4 -> Service | E4: ='Rate Card'!D4 -> Fixed | F4: =IF($A4="x",IFERROR(INDEX(DriverQty,MATCH($E4,DriverName,0)),0),0) -> 1 | G4: ='Rate Card'!I4 -> 120500 | I4: =IF($D4="Pass-through",0,MAX(MarginFloor,IF($H4="",MarginLever,$H4))) -> 0.225 | J4: =IF($D4="Pass-through",$G4,IF($I4>=1,$G4,ROUND($G4/(1-$I4),0))) -> 155484 | K4: =$F4*$J4 -> 155484 | L4: =$F4*$G4 -> 120500 | M4: =$F4*N('Rate Card'!E4) -> 70 | N4: =$F4*N('Rate Card'!G4) -> 18
B5: ='Rate Card'!A5 -> Medical | C5: ='Rate Card'!B5 -> Protocol Writing -Phase 4 | D5: ='Rate Card'!C5 -> Service | E5: ='Rate Card'!D5 -> Fixed | F5: =IF($A5="x",IFERROR(INDEX(DriverQty,MATCH($E5,DriverName,0)),0),0) -> 0 | G5: ='Rate Card'!I5 -> 120500 | I5: =IF($D5="Pass-through",0,MAX(MarginFloor,IF($H5="",MarginLever,$H5))) -> 0.225 | J5: =IF($D5="Pass-through",$G5,IF($I5>=1,$G5,ROUND($G5/(1-$I5),0))) -> 155484 | K5: =$F5*$J5 -> 0 | L5: =$F5*$G5 -> 0 | M5: =$F5*N('Rate Card'!E5) -> 0 | N5: =$F5*N('Rate Card'!G5) -> 0
A6: x | B6: ='Rate Card'!A6 -> Medical | C6: ='Rate Card'!B6 -> ICD (n=1; English) | D6: ='Rate Card'!C6 -> Service | E6: ='Rate Card'!D6 -> Fixed | F6: =IF($A6="x",IFERROR(INDEX(DriverQty,MATCH($E6,DriverName,0)),0),0) -> 1 | G6: ='Rate Card'!I6 -> 29100 | I6: =IF($D6="Pass-through",0,MAX(MarginFloor,IF($H6="",MarginLever,$H6))) -> 0.225 | J6: =IF($D6="Pass-through",$G6,IF($I6>=1,$G6,ROUND($G6/(1-$I6),0))) -> 37548 | K6: =$F6*$J6 -> 37548 | L6: =$F6*$G6 -> 29100 | M6: =$F6*N('Rate Card'!E6) -> 18 | N6: =$F6*N('Rate Card'!G6) -> 4
B7: ='Rate Card'!A7 -> Medical | C7: ='Rate Card'!B7 -> ICD + Ascent (n=1; English) | D7: ='Rate Card'!C7 -> Service | E7: ='Rate Card'!D7 -> Fixed | F7: =IF($A7="x",IFERROR(INDEX(DriverQty,MATCH($E7,DriverName,0)),0),0) -> 0 | G7: ='Rate Card'!I7 -> 30800 | I7: =IF($D7="Pass-through",0,MAX(MarginFloor,IF($H7="",MarginLever,$H7))) -> 0.225 | J7: =IF($D7="Pass-through",$G7,IF($I7>=1,$G7,ROUND($G7/(1-$I7),0))) -> 39742 | K7: =$F7*$J7 -> 0 | L7: =$F7*$G7 -> 0 | M7: =$F7*N('Rate Card'!E7) -> 0 | N7: =$F7*N('Rate Card'!G7) -> 0
A8: x | B8: ='Rate Card'!A8 -> Medical | C8: ='Rate Card'!B8 -> Data variable enlisting for DCF/CRF preparation | D8: ='Rate Card'!C8 -> Service | E8: ='Rate Card'!D8 -> Fixed | F8: =IF($A8="x",IFERROR(INDEX(DriverQty,MATCH($E8,DriverName,0)),0),0) -> 1 | G8: ='Rate Card'!I8 -> 8700 | I8: =IF($D8="Pass-through",0,MAX(MarginFloor,IF($H8="",MarginLever,$H8))) -> 0.225 | J8: =IF($D8="Pass-through",$G8,IF($I8>=1,$G8,ROUND($G8/(1-$I8),0))) -> 11226 | K8: =$F8*$J8 -> 11226 | L8: =$F8*$G8 -> 8700 | M8: =$F8*N('Rate Card'!E8) -> 6 | N8: =$F8*N('Rate Card'!G8) -> 1
A9: x | B9: ='Rate Card'!A9 -> Medical | C9: ='Rate Card'!B9 -> Site Feasibility Questionnaire (Post Concept Finalization) | D9: ='Rate Card'!C9 -> Service | E9: ='Rate Card'!D9 -> Fixed | F9: =IF($A9="x",IFERROR(INDEX(DriverQty,MATCH($E9,DriverName,0)),0),0) -> 1 | G9: ='Rate Card'!I9 -> 6325 | I9: =IF($D9="Pass-through",0,MAX(MarginFloor,IF($H9="",MarginLever,$H9))) -> 0.225 | J9: =IF($D9="Pass-through",$G9,IF($I9>=1,$G9,ROUND($G9/(1-$I9),0))) -> 8161 | K9: =$F9*$J9 -> 8161 | L9: =$F9*$G9 -> 6325 | M9: =$F9*N('Rate Card'!E9) -> 3.5 | N9: =$F9*N('Rate Card'!G9) -> 1
B10: ='Rate Card'!A10 -> Medical | C10: ='Rate Card'!B10 -> Feasibility Questionnaire (e.g. Study Feasibility/Survey) | D10: ='Rate Card'!C10 -> Service | E10: ='Rate Card'!D10 -> Fixed | F10: =IF($A10="x",IFERROR(INDEX(DriverQty,MATCH($E10,DriverName,0)),0),0) -> 0 | G10: ='Rate Card'!I10 -> 9325 | I10: =IF($D10="Pass-through",0,MAX(MarginFloor,IF($H10="",MarginLever,$H10))) -> 0.225 | J10: =IF($D10="Pass-through",$G10,IF($I10>=1,$G10,ROUND($G10/(1-$I10),0))) -> 12032 | K10: =$F10*$J10 -> 0 | L10: =$F10*$G10 -> 0 | M10: =$F10*N('Rate Card'!E10) -> 0 | N10: =$F10*N('Rate Card'!G10) -> 0
B11: ='Rate Card'!A11 -> Medical | C11: ='Rate Card'!B11 -> Investigator meeting deck | D11: ='Rate Card'!C11 -> Service | E11: ='Rate Card'!D11 -> Fixed | F11: =IF($A11="x",IFERROR(INDEX(DriverQty,MATCH($E11,DriverName,0)),0),0) -> 0 | G11: ='Rate Card'!I11 -> 18650 | I11: =IF($D11="Pass-through",0,MAX(MarginFloor,IF($H11="",MarginLever,$H11))) -> 0.225 | J11: =IF($D11="Pass-through",$G11,IF($I11>=1,$G11,ROUND($G11/(1-$I11),0))) -> 24065 | K11: =$F11*$J11 -> 0 | L11: =$F11*$G11 -> 0 | M11: =$F11*N('Rate Card'!E11) -> 0 | N11: =$F11*N('Rate Card'!G11) -> 0
A12: x | B12: ='Rate Card'!A12 -> Medical | C12: ='Rate Card'!B12 -> Protocol Training Deck | D12: ='Rate Card'!C12 -> Service | E12: ='Rate Card'!D12 -> Fixed | F12: =IF($A12="x",IFERROR(INDEX(DriverQty,MATCH($E12,DriverName,0)),0),0) -> 1 | G12: ='Rate Card'!I12 -> 20400 | I12: =IF($D12="Pass-through",0,MAX(MarginFloor,IF($H12="",MarginLever,$H12))) -> 0.225 | J12: =IF($D12="Pass-through",$G12,IF($I12>=1,$G12,ROUND($G12/(1-$I12),0))) -> 26323 | K12: =$F12*$J12 -> 26323 | L12: =$F12*$G12 -> 20400 | M12: =$F12*N('Rate Card'!E12) -> 12 | N12: =$F12*N('Rate Card'!G12) -> 3
B13: ='Rate Card'!A13 -> Medical | C13: ='Rate Card'!B13 -> SAP - Dummy tables (overlaps with stats) | D13: ='Rate Card'!C13 -> Service | E13: ='Rate Card'!D13 -> Fixed | F13: =IF($A13="x",IFERROR(INDEX(DriverQty,MATCH($E13,DriverName,0)),0),0) -> 0 | G13: ='Rate Card'!I13 -> 23400 | I13: =IF($D13="Pass-through",0,MAX(MarginFloor,IF($H13="",MarginLever,$H13))) -> 0.225 | J13: =IF($D13="Pass-through",$G13,IF($I13>=1,$G13,ROUND($G13/(1-$I13),0))) -> 30194 | K13: =$F13*$J13 -> 0 | L13: =$F13*$G13 -> 0 | M13: =$F13*N('Rate Card'!E13) -> 0 | N13: =$F13*N('Rate Card'!G13) -> 0
B14: ='Rate Card'!A14 -> Medical | C14: ='Rate Card'!B14 -> SAR (overlaps with stats) (review, varies as per study depth) | D14: ='Rate Card'!C14 -> Service | E14: ='Rate Card'!D14 -> Fixed | F14: =IF($A14="x",IFERROR(INDEX(DriverQty,MATCH($E14,DriverName,0)),0),0) -> 0 | G14: ='Rate Card'!I14 -> 72000 | I14: =IF($D14="Pass-through",0,MAX(MarginFloor,IF($H14="",MarginLever,$H14))) -> 0.225 | J14: =IF($D14="Pass-through",$G14,IF($I14>=1,$G14,ROUND($G14/(1-$I14),0))) -> 92903 | K14: =$F14*$J14 -> 0 | L14: =$F14*$G14 -> 0 | M14: =$F14*N('Rate Card'!E14) -> 0 | N14: =$F14*N('Rate Card'!G14) -> 0
B15: ='Rate Card'!A15 -> Medical | C15: ='Rate Card'!B15 -> Statistical Analysis (Varies based on quantum and variables) (review) | D15: ='Rate Card'!C15 -> Service | E15: ='Rate Card'!D15 -> Fixed | F15: =IF($A15="x",IFERROR(INDEX(DriverQty,MATCH($E15,DriverName,0)),0),0) -> 0 | G15: ='Rate Card'!I15 -> 48000 | I15: =IF($D15="Pass-through",0,MAX(MarginFloor,IF($H15="",MarginLever,$H15))) -> 0.225 | J15: =IF($D15="Pass-through",$G15,IF($I15>=1,$G15,ROUND($G15/(1-$I15),0))) -> 61935 | K15: =$F15*$J15 -> 0 | L15: =$F15*$G15 -> 0 | M15: =$F15*N('Rate Card'!E15) -> 0 | N15: =$F15*N('Rate Card'!G15) -> 0
B16: ='Rate Card'!A16 -> Medical | C16: ='Rate Card'!B16 -> Slide Deck (25 slides; Can vary based on Objective; includes RFP deck, interim report etc.) | D16: ='Rate Card'!C16 -> Service | E16: ='Rate Card'!D16 -> Fixed | F16: =IF($A16="x",IFERROR(INDEX(DriverQty,MATCH($E16,DriverName,0)),0),0) -> 0 | G16: ='Rate Card'!I16 -> 50600 | I16: =IF($D16="Pass-through",0,MAX(MarginFloor,IF($H16="",MarginLever,$H16))) -> 0.225 | J16: =IF($D16="Pass-through",$G16,IF($I16>=1,$G16,ROUND($G16/(1-$I16),0))) -> 65290 | K16: =$F16*$J16 -> 0 | L16: =$F16*$G16 -> 0 | M16: =$F16*N('Rate Card'!E16) -> 0 | N16: =$F16*N('Rate Card'!G16) -> 0
A17: x | B17: ='Rate Card'!A17 -> Medical | C17: ='Rate Card'!B17 -> CSR | D17: ='Rate Card'!C17 -> Service | E17: ='Rate Card'!D17 -> Fixed | F17: =IF($A17="x",IFERROR(INDEX(DriverQty,MATCH($E17,DriverName,0)),0),0) -> 1 | G17: ='Rate Card'!I17 -> 110600 | I17: =IF($D17="Pass-through",0,MAX(MarginFloor,IF($H17="",MarginLever,$H17))) -> 0.225 | J17: =IF($D17="Pass-through",$G17,IF($I17>=1,$G17,ROUND($G17/(1-$I17),0))) -> 142710 | K17: =$F17*$J17 -> 142710 | L17: =$F17*$G17 -> 110600 | M17: =$F17*N('Rate Card'!E17) -> 28 | N17: =$F17*N('Rate Card'!G17) -> 28
B18: ='Rate Card'!A18 -> Medical | C18: ='Rate Card'!B18 -> Journal Selection and list development | D18: ='Rate Card'!C18 -> Service | E18: ='Rate Card'!D18 -> Fixed | F18: =IF($A18="x",IFERROR(INDEX(DriverQty,MATCH($E18,DriverName,0)),0),0) -> 0 | G18: ='Rate Card'!I18 -> 12100 | I18: =IF($D18="Pass-through",0,MAX(MarginFloor,IF($H18="",MarginLever,$H18))) -> 0.225 | J18: =IF($D18="Pass-through",$G18,IF($I18>=1,$G18,ROUND($G18/(1-$I18),0))) -> 15613 | K18: =$F18*$J18 -> 0 | L18: =$F18*$G18 -> 0 | M18: =$F18*N('Rate Card'!E18) -> 0 | N18: =$F18*N('Rate Card'!G18) -> 0
B19: ='Rate Card'!A19 -> Medical | C19: ='Rate Card'!B19 -> MS writing (Original article for clinical studies) | D19: ='Rate Card'!C19 -> Service | E19: ='Rate Card'!D19 -> Fixed | F19: =IF($A19="x",IFERROR(INDEX(DriverQty,MATCH($E19,DriverName,0)),0),0) -> 0 | G19: ='Rate Card'!I19 -> 148000 | I19: =IF($D19="Pass-through",0,MAX(MarginFloor,IF($H19="",MarginLever,$H19))) -> 0.225 | J19: =IF($D19="Pass-through",$G19,IF($I19>=1,$G19,ROUND($G19/(1-$I19),0))) -> 190968 | K19: =$F19*$J19 -> 0 | L19: =$F19*$G19 -> 0 | M19: =$F19*N('Rate Card'!E19) -> 0 | N19: =$F19*N('Rate Card'!G19) -> 0
B20: ='Rate Card'!A20 -> Medical | C20: ='Rate Card'!B20 -> MS writing - Review article (Narrative/SLR) (including literature search and finalization) | D20: ='Rate Card'!C20 -> Service | E20: ='Rate Card'!D20 -> Fixed | F20: =IF($A20="x",IFERROR(INDEX(DriverQty,MATCH($E20,DriverName,0)),0),0) -> 0 | G20: ='Rate Card'!I20 -> 181000 | I20: =IF($D20="Pass-through",0,MAX(MarginFloor,IF($H20="",MarginLever,$H20))) -> 0.225 | J20: =IF($D20="Pass-through",$G20,IF($I20>=1,$G20,ROUND($G20/(1-$I20),0))) -> 233548 | K20: =$F20*$J20 -> 0 | L20: =$F20*$G20 -> 0 | M20: =$F20*N('Rate Card'!E20) -> 0 | N20: =$F20*N('Rate Card'!G20) -> 0
B21: ='Rate Card'!A21 -> Medical | C21: ='Rate Card'!B21 -> Abstract for Conference (1st draft for Client's review and approval) | D21: ='Rate Card'!C21 -> Service | E21: ='Rate Card'!D21 -> Fixed | F21: =IF($A21="x",IFERROR(INDEX(DriverQty,MATCH($E21,DriverName,0)),0),0) -> 0 | G21: ='Rate Card'!I21 -> 119500 | I21: =IF($D21="Pass-through",0,MAX(MarginFloor,IF($H21="",MarginLever,$H21))) -> 0.225 | J21: =IF($D21="Pass-through",$G21,IF($I21>=1,$G21,ROUND($G21/(1-$I21),0))) -> 154194 | K21: =$F21*$J21 -> 0 | L21: =$F21*$G21 -> 0 | M21: =$F21*N('Rate Card'!E21) -> 0 | N21: =$F21*N('Rate Card'!G21) -> 0
B22: ='Rate Card'!A22 -> Medical | C22: ='Rate Card'!B22 -> Poster in ppt format (1st draft for Client's review and approval) | D22: ='Rate Card'!C22 -> Service | E22: ='Rate Card'!D22 -> Fixed | F22: =IF($A22="x",IFERROR(INDEX(DriverQty,MATCH($E22,DriverName,0)),0),0) -> 0 | G22: ='Rate Card'!I22 -> 45200 | I22: =IF($D22="Pass-through",0,MAX(MarginFloor,IF($H22="",MarginLever,$H22))) -> 0.225 | J22: =IF($D22="Pass-through",$G22,IF($I22>=1,$G22,ROUND($G22/(1-$I22),0))) -> 58323 | K22: =$F22*$J22 -> 0 | L22: =$F22*$G22 -> 0 | M22: =$F22*N('Rate Card'!E22) -> 0 | N22: =$F22*N('Rate Card'!G22) -> 0
B23: ='Rate Card'!A23 -> Medical | C23: ='Rate Card'!B23 -> Submission package preparation and journal submission (varies as per journal requirement) | D23: ='Rate Card'!C23 -> Service | E23: ='Rate Card'!D23 -> Fixed | F23: =IF($A23="x",IFERROR(INDEX(DriverQty,MATCH($E23,DriverName,0)),0),0) -> 0 | G23: ='Rate Card'!I23 -> 36250 | I23: =IF($D23="Pass-through",0,MAX(MarginFloor,IF($H23="",MarginLever,$H23))) -> 0.225 | J23: =IF($D23="Pass-through",$G23,IF($I23>=1,$G23,ROUND($G23/(1-$I23),0))) -> 46774 | K23: =$F23*$J23 -> 0 | L23: =$F23*$G23 -> 0 | M23: =$F23*N('Rate Card'!E23) -> 0 | N23: =$F23*N('Rate Card'!G23) -> 0
B24: ='Rate Card'!A24 -> Medical | C24: ='Rate Card'!B24 -> Minor Revisions of Submitted Manuscript and Re-submission (Reviewer comments post submission) | D24: ='Rate Card'!C24 -> Service | E24: ='Rate Card'!D24 -> Fixed | F24: =IF($A24="x",IFERROR(INDEX(DriverQty,MATCH($E24,DriverName,0)),0),0) -> 0 | G24: ='Rate Card'!I24 -> 23400 | I24: =IF($D24="Pass-through",0,MAX(MarginFloor,IF($H24="",MarginLever,$H24))) -> 0.225 | J24: =IF($D24="Pass-through",$G24,IF($I24>=1,$G24,ROUND($G24/(1-$I24),0))) -> 30194 | K24: =$F24*$J24 -> 0 | L24: =$F24*$G24 -> 0 | M24: =$F24*N('Rate Card'!E24) -> 0 | N24: =$F24*N('Rate Card'!G24) -> 0
B25: ='Rate Card'!A25 -> Medical | C25: ='Rate Card'!B25 -> Major Revisions of Submitted Manuscript and Re-submission (Reviewer comments post submission) | D25: ='Rate Card'!C25 -> Service | E25: ='Rate Card'!D25 -> Fixed | F25: =IF($A25="x",IFERROR(INDEX(DriverQty,MATCH($E25,DriverName,0)),0),0) -> 0 | G25: ='Rate Card'!I25 -> 74000 | I25: =IF($D25="Pass-through",0,MAX(MarginFloor,IF($H25="",MarginLever,$H25))) -> 0.225 | J25: =IF($D25="Pass-through",$G25,IF($I25>=1,$G25,ROUND($G25/(1-$I25),0))) -> 95484 | K25: =$F25*$J25 -> 0 | L25: =$F25*$G25 -> 0 | M25: =$F25*N('Rate Card'!E25) -> 0 | N25: =$F25*N('Rate Card'!G25) -> 0
B26: ='Rate Card'!A26 -> Medical | C26: ='Rate Card'!B26 -> Other Activities (Grant writing, RFP documents) | D26: ='Rate Card'!C26 -> Service | E26: ='Rate Card'!D26 -> Fixed | F26: =IF($A26="x",IFERROR(INDEX(DriverQty,MATCH($E26,DriverName,0)),0),0) -> 0 | G26: ='Rate Card'!I26 -> 74000 | I26: =IF($D26="Pass-through",0,MAX(MarginFloor,IF($H26="",MarginLever,$H26))) -> 0.225 | J26: =IF($D26="Pass-through",$G26,IF($I26>=1,$G26,ROUND($G26/(1-$I26),0))) -> 95484 | K26: =$F26*$J26 -> 0 | L26: =$F26*$G26 -> 0 | M26: =$F26*N('Rate Card'!E26) -> 0 | N26: =$F26*N('Rate Card'!G26) -> 0
A27: x | B27: ='Rate Card'!A27 -> SSU | C27: ='Rate Card'!B27 -> Site Identification (per site) | D27: ='Rate Card'!C27 -> Service | E27: ='Rate Card'!D27 -> Per site | F27: =IF($A27="x",IFERROR(INDEX(DriverQty,MATCH($E27,DriverName,0)),0),0) -> 5 | G27: ='Rate Card'!I27 -> 400 | I27: =IF($D27="Pass-through",0,MAX(MarginFloor,IF($H27="",MarginLever,$H27))) -> 0.225 | J27: =IF($D27="Pass-through",$G27,IF($I27>=1,$G27,ROUND($G27/(1-$I27),0))) -> 516 | K27: =$F27*$J27 -> 2580 | L27: =$F27*$G27 -> 2000 | M27: =$F27*N('Rate Card'!E27) -> 2.5 | N27: =$F27*N('Rate Card'!G27) -> 0
B28: ='Rate Card'!A28 -> SSU | C28: ='Rate Card'!B28 -> Pre-feasibility form development | D28: ='Rate Card'!C28 -> Service | E28: ='Rate Card'!D28 -> Fixed | F28: =IF($A28="x",IFERROR(INDEX(DriverQty,MATCH($E28,DriverName,0)),0),0) -> 0 | G28: ='Rate Card'!I28 -> 3200 | I28: =IF($D28="Pass-through",0,MAX(MarginFloor,IF($H28="",MarginLever,$H28))) -> 0.225 | J28: =IF($D28="Pass-through",$G28,IF($I28>=1,$G28,ROUND($G28/(1-$I28),0))) -> 4129 | K28: =$F28*$J28 -> 0 | L28: =$F28*$G28 -> 0 | M28: =$F28*N('Rate Card'!E28) -> 0 | N28: =$F28*N('Rate Card'!G28) -> 0
A29: x | B29: ='Rate Card'!A29 -> SSU | C29: ='Rate Card'!B29 -> Pre-feasibility | D29: ='Rate Card'!C29 -> Service | E29: ='Rate Card'!D29 -> Per site | F29: =IF($A29="x",IFERROR(INDEX(DriverQty,MATCH($E29,DriverName,0)),0),0) -> 5 | G29: ='Rate Card'!I29 -> 1200 | I29: =IF($D29="Pass-through",0,MAX(MarginFloor,IF($H29="",MarginLever,$H29))) -> 0.225 | J29: =IF($D29="Pass-through",$G29,IF($I29>=1,$G29,ROUND($G29/(1-$I29),0))) -> 1548 | K29: =$F29*$J29 -> 7740 | L29: =$F29*$G29 -> 6000 | M29: =$F29*N('Rate Card'!E29) -> 7.5 | N29: =$F29*N('Rate Card'!G29) -> 0
A30: x | B30: ='Rate Card'!A30 -> SSU | C30: ='Rate Card'!B30 -> Feasibility | D30: ='Rate Card'!C30 -> Service | E30: ='Rate Card'!D30 -> Per site | F30: =IF($A30="x",IFERROR(INDEX(DriverQty,MATCH($E30,DriverName,0)),0),0) -> 5 | G30: ='Rate Card'!I30 -> 4200 | I30: =IF($D30="Pass-through",0,MAX(MarginFloor,IF($H30="",MarginLever,$H30))) -> 0.225 | J30: =IF($D30="Pass-through",$G30,IF($I30>=1,$G30,ROUND($G30/(1-$I30),0))) -> 5419 | K30: =$F30*$J30 -> 27095 | L30: =$F30*$G30 -> 21000 | M30: =$F30*N('Rate Card'!E30) -> 7.5 | N30: =$F30*N('Rate Card'!G30) -> 5
B31: ='Rate Card'!A31 -> SSU | C31: ='Rate Card'!B31 -> Feasibility Report | D31: ='Rate Card'!C31 -> Service | E31: ='Rate Card'!D31 -> Fixed | F31: =IF($A31="x",IFERROR(INDEX(DriverQty,MATCH($E31,DriverName,0)),0),0) -> 0 | G31: ='Rate Card'!I31 -> 3200 | I31: =IF($D31="Pass-through",0,MAX(MarginFloor,IF($H31="",MarginLever,$H31))) -> 0.225 | J31: =IF($D31="Pass-through",$G31,IF($I31>=1,$G31,ROUND($G31/(1-$I31),0))) -> 4129 | K31: =$F31*$J31 -> 0 | L31: =$F31*$G31 -> 0 | M31: =$F31*N('Rate Card'!E31) -> 0 | N31: =$F31*N('Rate Card'!G31) -> 0
A32: x | B32: ='Rate Card'!A32 -> SSU | C32: ='Rate Card'!B32 -> Essential document collection | D32: ='Rate Card'!C32 -> Service | E32: ='Rate Card'!D32 -> Per site | F32: =IF($A32="x",IFERROR(INDEX(DriverQty,MATCH($E32,DriverName,0)),0),0) -> 5 | G32: ='Rate Card'!I32 -> 1600 | I32: =IF($D32="Pass-through",0,MAX(MarginFloor,IF($H32="",MarginLever,$H32))) -> 0.225 | J32: =IF($D32="Pass-through",$G32,IF($I32>=1,$G32,ROUND($G32/(1-$I32),0))) -> 2065 | K32: =$F32*$J32 -> 10325 | L32: =$F32*$G32 -> 8000 | M32: =$F32*N('Rate Card'!E32) -> 10 | N32: =$F32*N('Rate Card'!G32) -> 0
B33: ='Rate Card'!A33 -> SSU | C33: ='Rate Card'!B33 -> PSQV - preparation | D33: ='Rate Card'!C33 -> Service | E33: ='Rate Card'!D33 -> Per site | F33: =IF($A33="x",IFERROR(INDEX(DriverQty,MATCH($E33,DriverName,0)),0),0) -> 0 | G33: ='Rate Card'!I33 -> 3200 | I33: =IF($D33="Pass-through",0,MAX(MarginFloor,IF($H33="",MarginLever,$H33))) -> 0.225 | J33: =IF($D33="Pass-through",$G33,IF($I33>=1,$G33,ROUND($G33/(1-$I33),0))) -> 4129 | K33: =$F33*$J33 -> 0 | L33: =$F33*$G33 -> 0 | M33: =$F33*N('Rate Card'!E33) -> 0 | N33: =$F33*N('Rate Card'!G33) -> 0
B34: ='Rate Card'!A34 -> SSU | C34: ='Rate Card'!B34 -> PSQV - visit & report | D34: ='Rate Card'!C34 -> Service | E34: ='Rate Card'!D34 -> Per site | F34: =IF($A34="x",IFERROR(INDEX(DriverQty,MATCH($E34,DriverName,0)),0),0) -> 0 | G34: ='Rate Card'!I34 -> 6400 | I34: =IF($D34="Pass-through",0,MAX(MarginFloor,IF($H34="",MarginLever,$H34))) -> 0.225 | J34: =IF($D34="Pass-through",$G34,IF($I34>=1,$G34,ROUND($G34/(1-$I34),0))) -> 8258 | K34: =$F34*$J34 -> 0 | L34: =$F34*$G34 -> 0 | M34: =$F34*N('Rate Card'!E34) -> 0 | N34: =$F34*N('Rate Card'!G34) -> 0
B35: ='Rate Card'!A35 -> SSU | C35: ='Rate Card'!B35 -> PSQV - local travel | D35: ='Rate Card'!C35 -> Service | E35: ='Rate Card'!D35 -> Per site | F35: =IF($A35="x",IFERROR(INDEX(DriverQty,MATCH($E35,DriverName,0)),0),0) -> 0 | G35: ='Rate Card'!I35 -> 4000 | I35: =IF($D35="Pass-through",0,MAX(MarginFloor,IF($H35="",MarginLever,$H35))) -> 0.225 | J35: =IF($D35="Pass-through",$G35,IF($I35>=1,$G35,ROUND($G35/(1-$I35),0))) -> 5161 | K35: =$F35*$J35 -> 0 | L35: =$F35*$G35 -> 0 | M35: =$F35*N('Rate Card'!E35) -> 0 | N35: =$F35*N('Rate Card'!G35) -> 0
B36: ='Rate Card'!A36 -> SSU | C36: ='Rate Card'!B36 -> PSQV - Out-station travel | D36: ='Rate Card'!C36 -> Service | E36: ='Rate Card'!D36 -> Per site | F36: =IF($A36="x",IFERROR(INDEX(DriverQty,MATCH($E36,DriverName,0)),0),0) -> 0 | G36: ='Rate Card'!I36 -> 8000 | I36: =IF($D36="Pass-through",0,MAX(MarginFloor,IF($H36="",MarginLever,$H36))) -> 0.225 | J36: =IF($D36="Pass-through",$G36,IF($I36>=1,$G36,ROUND($G36/(1-$I36),0))) -> 10323 | K36: =$F36*$J36 -> 0 | L36: =$F36*$G36 -> 0 | M36: =$F36*N('Rate Card'!E36) -> 0 | N36: =$F36*N('Rate Card'!G36) -> 0
A37: x | B37: ='Rate Card'!A37 -> SSU | C37: ='Rate Card'!B37 -> CSA/MoU development | D37: ='Rate Card'!C37 -> Service | E37: ='Rate Card'!D37 -> Fixed | F37: =IF($A37="x",IFERROR(INDEX(DriverQty,MATCH($E37,DriverName,0)),0),0) -> 1 | G37: ='Rate Card'!I37 -> 8300 | I37: =IF($D37="Pass-through",0,MAX(MarginFloor,IF($H37="",MarginLever,$H37))) -> 0.225 | J37: =IF($D37="Pass-through",$G37,IF($I37>=1,$G37,ROUND($G37/(1-$I37),0))) -> 10710 | K37: =$F37*$J37 -> 10710 | L37: =$F37*$G37 -> 8300 | M37: =$F37*N('Rate Card'!E37) -> 8.5 | N37: =$F37*N('Rate Card'!G37) -> 0.5
A38: x | B38: ='Rate Card'!A38 -> SSU | C38: ='Rate Card'!B38 -> CSA/MoU negotiation | D38: ='Rate Card'!C38 -> Service | E38: ='Rate Card'!D38 -> Per site | F38: =IF($A38="x",IFERROR(INDEX(DriverQty,MATCH($E38,DriverName,0)),0),0) -> 5 | G38: ='Rate Card'!I38 -> 1600 | I38: =IF($D38="Pass-through",0,MAX(MarginFloor,IF($H38="",MarginLever,$H38))) -> 0.225 | J38: =IF($D38="Pass-through",$G38,IF($I38>=1,$G38,ROUND($G38/(1-$I38),0))) -> 2065 | K38: =$F38*$J38 -> 10325 | L38: =$F38*$G38 -> 8000 | M38: =$F38*N('Rate Card'!E38) -> 10 | N38: =$F38*N('Rate Card'!G38) -> 0
A39: x | B39: ='Rate Card'!A39 -> SSU | C39: ='Rate Card'!B39 -> EC Dossier preparation | D39: ='Rate Card'!C39 -> Service | E39: ='Rate Card'!D39 -> Per site | F39: =IF($A39="x",IFERROR(INDEX(DriverQty,MATCH($E39,DriverName,0)),0),0) -> 5 | G39: ='Rate Card'!I39 -> 3200 | I39: =IF($D39="Pass-through",0,MAX(MarginFloor,IF($H39="",MarginLever,$H39))) -> 0.225 | J39: =IF($D39="Pass-through",$G39,IF($I39>=1,$G39,ROUND($G39/(1-$I39),0))) -> 4129 | K39: =$F39*$J39 -> 20645 | L39: =$F39*$G39 -> 16000 | M39: =$F39*N('Rate Card'!E39) -> 20 | N39: =$F39*N('Rate Card'!G39) -> 0
A40: x | B40: ='Rate Card'!A40 -> SSU | C40: ='Rate Card'!B40 -> EC Dossier online submission | D40: ='Rate Card'!C40 -> Service | E40: ='Rate Card'!D40 -> Per site | F40: =IF($A40="x",IFERROR(INDEX(DriverQty,MATCH($E40,DriverName,0)),0),0) -> 5 | G40: ='Rate Card'!I40 -> 1600 | I40: =IF($D40="Pass-through",0,MAX(MarginFloor,IF($H40="",MarginLever,$H40))) -> 0.225 | J40: =IF($D40="Pass-through",$G40,IF($I40>=1,$G40,ROUND($G40/(1-$I40),0))) -> 2065 | K40: =$F40*$J40 -> 10325 | L40: =$F40*$G40 -> 8000 | M40: =$F40*N('Rate Card'!E40) -> 10 | N40: =$F40*N('Rate Card'!G40) -> 0
...
